<?xml version="1.0"?>
<robot name="fetch_gripper">

  <material name="Grey">
    <color rgba="0.901961 0.901961 0.901961 1"/>
  </material>

  <link name="pseudo_slider_link"/>
  <link name="pseudo_slider2_link"/>
  <link name="pseudo_yrot_link"/>

  <joint name="xslide" type="prismatic">
    <axis xyz="0 1 0"/>
    <origin xyz="0.0 0.0 0"/>
    <parent link="pseudo_slider_link"/>
    <child link="pseudo_slider2_link"/>
    <limit effort="1000.0" lower="-15" upper="15" velocity="5"/>
  </joint>

  <joint name="zslide" type="prismatic">
    <axis xyz="1 0 0"/>
    <origin xyz="0.0 0.0 0"/>
    <parent link="pseudo_slider2_link"/>
    <child link="pseudo_yrot_link"/>
    <limit effort="1000.0" lower="-15" upper="15" velocity="5"/>
  </joint>

  <joint name="yrot" type="continuous">
    <axis xyz="0 1 0"/>
    <origin xyz="0.0 0.0 0"/>
    <parent link="pseudo_yrot_link"/>
    <child link="gripper_link"/>
  </joint>

  <link name="gripper_link">
    <inertial>
      <origin rpy="0 0 0" xyz="-0.0900 -0.0001 -0.0017" />
      <mass value="1.5175" />
      <inertia ixx="0.0013" ixy="-0.0" ixz="0.0" iyy="0.0019" iyz="-0.0" izz="0.0024" />
    </inertial>
    <visual>
      <origin rpy="0 0 0" xyz="0 0 0" />
      <geometry>
        <mesh filename="meshes/gripper_link.obj" />
      </geometry>
      <material name="Grey" />
    </visual>
    <collision>
      <origin rpy="0 0 0" xyz="0 0 0" />
      <geometry>
        <mesh filename="meshes/gripper_link.STL" />
      </geometry>
    </collision>
  </link>

  <link name="r_gripper_finger_link">
    <inertial>
      <origin rpy="0 0 0" xyz="-0.01 0 0" />
      <mass value="0.0798" />
      <inertia ixx="0.002" ixy="0" ixz="0" iyy="0.0002" iyz="0" izz="0.0002" />
    </inertial>
    <visual>
      <origin rpy="0 0 0" xyz="0 0.101425 0" />
      <geometry>
        <mesh filename="meshes/r_gripper_finger_link.STL" />
      </geometry>
      <material name="">
        <color rgba="0.356 0.361 0.376 1" />
      </material>
    </visual>
    <collision>
      <origin rpy="0 0 0" xyz="0 -0.009 0" />
      <geometry>
  <box size="0.062 0.013 0.026"/>
      </geometry>
    </collision>
  </link>
  <joint name="r_gripper_finger_joint" type="prismatic">
    <origin rpy="0 0 0" xyz="0 0.015425 0" />
    <parent link="gripper_link" />
    <child link="r_gripper_finger_link" />
    <axis xyz="0 1 0" />
    <limit effort="60" lower="0.0" upper="0.05" velocity="0.05" /><dynamics damping="100.0" />
  </joint>

  <link name="l_gripper_finger_link">
    <inertial>
      <origin rpy="0 0 0" xyz="-0.01 0 0" />
      <mass value="0.0798" />
      <inertia ixx="0.002" ixy="0" ixz="0" iyy="0.0002" iyz="0" izz="0.0002" />
    </inertial>
    <visual>
      <origin rpy="0 0 0" xyz="0 -0.101425 0" />
      <geometry>
        <mesh filename="meshes/l_gripper_finger_link.STL" />
      </geometry>
      <material name="">
        <color rgba="0.356 0.361 0.376 1" />
      </material>
    </visual>
    <collision>
      <origin rpy="0 0 0" xyz="0 0.009 0" />
      <geometry>
  <box size="0.062 0.013 0.026"/>
      </geometry>
    </collision>
  </link>
  <joint name="l_gripper_finger_joint" type="prismatic">
    <origin rpy="0 0 0" xyz="0 -0.015425 0" />
    <parent link="gripper_link" />
    <child link="l_gripper_finger_link" />
    <axis xyz="0 -1 0" />
    <limit effort="60" lower="0.0" upper="0.05" velocity="0.05" /><dynamics damping="100.0" />
  </joint>
</robot>
