<?xml version="1.0" encoding="utf-8"?>
<!-- =================================================================================== -->
<!-- |    This document was autogenerated by xacro from /opt/ros/melodic/share/pr2_description/robots/pr2.urdf.xacro | -->
<!-- |    EDITING THIS FILE BY HAND IS NOT RECOMMENDED                                 | -->
<!-- =================================================================================== -->
<robot name="pr2">
  <!--TODO Define and give source-->
  <!-- ============================   Shoulder   ============================ -->
  <!-- ============================   Upper Arm   ============================ -->
  <!-- ============================   Forearm   ============================ -->
  <!-- DATA SOURCES -->
  <!-- all link offsets, CG, limits are obtained from Function Engineering spreadsheet 090224_link_data.xls unless stated otherwise -->
  <!-- all link geometry sizes are obtained from Function provided CAD model unless stated otherwise -->
  <!-- all simplified collision geometry are hand approximated from CAD model, sometimes from respective bounding boxes -->
  <!-- This is the 'effective' wheel radius. Wheel radius for uncompressed wheel is 0.079.  mp 20080801 -->
  <material name="Blue">
    <color rgba="0.0 0.0 0.8 1.0"/>
  </material>
  <material name="Green">
    <color rgba="0.0 0.8 0.0 1.0"/>
  </material>
  <material name="Grey">
    <color rgba="0.7 0.7 0.7 1.0"/>
  </material>
  <material name="Grey2">
    <color rgba="0.9 0.9 0.9 1.0"/>
  </material>
  <material name="Red">
    <color rgba="0.8 0.0 0.0 1.0"/>
  </material>
  <material name="White">
    <color rgba="1.0 1.0 1.0 1.0"/>
  </material>
  <material name="Black">
    <color rgba="0.1 0.1 0.1 1.0"/>
  </material>
  <material name="LightGrey">
    <color rgba="0.6 0.6 0.6 1.0"/>
  </material>
  <material name="Caster">
    <texture filename="package://pr2_description/materials/textures/pr2_caster_texture.png"/>
  </material>
  <material name="Wheel_l">
    <texture filename="package://pr2_description/materials/textures/pr2_wheel_left.png"/>
  </material>
  <material name="Wheel_r">
    <texture filename="package://pr2_description/materials/textures/pr2_wheel_right.png"/>
  </material>
  <material name="RollLinks">
    <texture filename="package://pr2_description/materials/textures/pr2_wheel_left.png"/>
  </material>
  <!-- Now we can start using the macros included above to define the actual PR2 -->

  <!-- Wrist flex , Wrist roll -->
  <link name="pseudo_slider_link"/>
  <link name="pseudo_slider2_link"/>
  <link name="pseudo_yrot_link"/>

  <joint name="xslide" type="prismatic">
    <axis xyz="0 1 0"/>
    <origin xyz="0.0 0.0 0"/>
    <parent link="pseudo_slider_link"/>
    <child link="pseudo_slider2_link"/>
    <limit effort="1000.0" lower="-15" upper="15" velocity="5"/>
  </joint>

  <joint name="zslide" type="prismatic">
    <axis xyz="1 0 0"/>
    <origin xyz="0.0 0.0 0"/>
    <parent link="pseudo_slider2_link"/>
    <child link="pseudo_yrot_link"/>
    <limit effort="1000.0" lower="-15" upper="15" velocity="5"/>
  </joint>

  <joint name="yrot" type="continuous">
    <axis xyz="0 1 0"/>
    <origin xyz="0.0 0.0 0"/>
    <parent link="pseudo_yrot_link"/>
    <child link="r_gripper_palm_link"/>
  </joint>

 <link name="r_gripper_palm_link">
    <inertial>
      <mass value="0.58007"/>
      <origin rpy="0 0 0" xyz="0.06623 0.00053 -0.00119"/>
      <inertia ixx="0.00035223921" ixy="-0.00001580476" ixz="-0.00000091750" iyy="0.00067741312" iyz="-0.00000059554" izz="0.00086563316"/>
    </inertial>
    <visual>
      <origin rpy="0 0 0" xyz="0 0 0"/>
      <geometry>
        <mesh filename="package://pr2_description/meshes/gripper_v0/gripper_palm.dae"/>
      </geometry>
      <material name="Red"/>
    </visual>
    <collision>
      <origin rpy="0 0 0" xyz="0 0 0"/>
      <geometry>
        <mesh filename="package://pr2_description/meshes/gripper_v0/gripper_palm.stl"/>
      </geometry>
    </collision>
  </link>
  <joint name="r_gripper_led_joint" type="fixed">
    <!--  Need to check if we need a positive or negative Z term -->
    <origin xyz="0.0513 0.0 .0244"/>
    <parent link="r_gripper_palm_link"/>
    <child link="r_gripper_led_frame"/>
  </joint>
  <link name="r_gripper_led_frame"/>
  <joint name="r_gripper_motor_accelerometer_joint" type="fixed">
    <origin rpy="0 0 0" xyz="0 0 0"/>
    <parent link="r_gripper_palm_link"/>
    <child link="r_gripper_motor_accelerometer_link"/>
  </joint>
  <link name="r_gripper_motor_accelerometer_link">
    <inertial>
      <mass value="0.001"/>
      <origin rpy="0 0 0" xyz="0 0 0"/>
      <inertia ixx="0.001" ixy="0.0" ixz="0.0" iyy="0.001" iyz="0.0" izz="0.001"/>
    </inertial>
    <visual>
      <origin rpy="0 0 0" xyz="0 0 0"/>
      <geometry>
        <box size="0.001 0.001 0.001"/>
      </geometry>
    </visual>
    <collision>
      <origin rpy="0 0 0" xyz="0 0 0"/>
      <geometry>
        <box size="0.001 0.001 0.001"/>
      </geometry>
    </collision>
  </link>
  <joint name="r_gripper_tool_joint" type="fixed">
    <origin rpy="0 0 0" xyz="0.18 0 0"/>
    <parent link="r_gripper_palm_link"/>
    <child link="r_gripper_tool_frame"/>
  </joint>
  <link name="r_gripper_tool_frame"/>
  <!-- actuated motor screw joint -->
  <link name="r_gripper_motor_slider_link">
    <inertial>
      <mass value="0.01"/>
      <origin rpy="0 0 0" xyz="0 0 0"/>
      <inertia ixx="0.001" ixy="0.0" ixz="0.0" iyy="0.001" iyz="0.0" izz="0.001"/>
    </inertial>
    <!-- for debugging only
      <visual>
        <origin xyz="0 0 0" rpy="1.5708 0 0" />
        <geometry>
          <cylinder length="0.002" radius="0.025"/>
        </geometry>
      </visual>
      <collision>
        <origin xyz="0 0 0" rpy="1.5708 0 0" />
        <geometry>
          <cylinder length="0.002" radius="0.025"/>
        </geometry>
      </collision>
      -->
  </link>
  <joint name="r_gripper_motor_slider_joint" type="prismatic">
    <origin rpy="0 0 0" xyz="0.16828 0 0"/>
    <axis xyz="1 0 0"/>
    <parent link="r_gripper_palm_link"/>
    <child link="r_gripper_motor_slider_link"/>
    <limit effort="1000.0" lower="-0.1" upper="0.1" velocity="0.2"/>
  </joint>
  <link name="r_gripper_motor_screw_link">
    <inertial>
      <mass value="0.01"/>
      <origin rpy="0 0 0" xyz="0 0 0"/>
      <inertia ixx="0.0001" ixy="0.0" ixz="0.0" iyy="0.0001" iyz="0.0" izz="0.0001"/>
    </inertial>
    <!-- for debugging only
      <visual>
        <origin xyz="0 0 0" rpy="0 0 0" />
        <geometry>
          <box size="0.05 0.001 0.05" />
        </geometry>
      </visual>
      <collision>
        <origin xyz="0 0 0" rpy="0 0 0" />
        <geometry>
          <box size="0.05 0.001 0.05" />
        </geometry>
      </collision>
      -->
  </link>
  <joint name="r_gripper_motor_screw_joint" type="continuous">
    <origin rpy="0 0 0" xyz="0.0 0 0"/>
    <axis xyz="0 1 0"/>
    <parent link="r_gripper_motor_slider_link"/>
    <child link="r_gripper_motor_screw_link"/>
    <dynamics damping="0.0001"/>
  </joint>
  <!-- Finger proximal digit -->
  <joint name="r_gripper_l_finger_joint" type="revolute">
    <axis xyz="0 0 1"/>
    <!-- limits on passive finger and finger top joints without
         transmission are not enforced by safety controllers.
         The lower/upper limits and are enforced in PR2 simulation and
         effort and velocity limits are ignored. This is also needed because
         these joints are declared revolute rather than continuous.-->
    <limit effort="1000.0" lower="0.0" upper="0.548" velocity="0.5"/>
    <dynamics damping="0.02"/>
    <origin rpy="0 0 0" xyz="0.07691 0.01 0"/>
    <parent link="r_gripper_palm_link"/>
    <child link="r_gripper_l_finger_link"/>
  </joint>
  <link name="r_gripper_l_finger_link">
    <inertial>
      <mass value="0.17126"/>
      <origin rpy="0 0 0" xyz="0.03598 0.01730 -0.00164"/>
      <inertia ixx="0.00007756198" ixy="0.00000149095" ixz="-0.00000983385" iyy="0.00019708305" iyz="-0.00000306125" izz="0.00018105446"/>
    </inertial>
    <visual>
      <origin rpy="0 0 0" xyz="0 0 0"/>
      <geometry>
        <mesh filename="package://pr2_description/meshes/gripper_v0/l_finger.dae"/>
      </geometry>
      <material name="Grey"/>
    </visual>
    <collision>
      <origin rpy="0 0 0" xyz="0 0 0"/>
      <geometry>
        <mesh filename="package://pr2_description/meshes/gripper_v0/l_finger.stl"/>
      </geometry>
    </collision>
  </link>
  <!-- Finger proximal digit -->
  <joint name="r_gripper_r_finger_joint" type="revolute">
    <axis xyz="0 0 -1"/>
    <origin rpy="0 0 0" xyz="0.07691 -0.01 0"/>
    <!-- limits on passive finger and finger top joints without
         transmission are not enforced by safety controllers.
         The lower/upper limits and are enforced in PR2 simulation and
         effort and velocity limits are ignored. This is also needed because
         these joints are declared revolute rather than continuous.-->
    <limit effort="1000.0" lower="0.0" upper="0.548" velocity="0.5"/>
    <dynamics damping="0.02"/>
    <mimic joint="r_gripper_l_finger_joint" multiplier="1" offset="0"/>
    <parent link="r_gripper_palm_link"/>
    <child link="r_gripper_r_finger_link"/>
  </joint>
  <link name="r_gripper_r_finger_link">
    <inertial>
      <mass value="0.17389"/>
      <origin rpy="0 0 0" xyz="0.03576 -0.01736 -0.00095"/>
      <inertia ixx="0.00007738410" ixy="-0.00000209309" ixz="-0.00000836228" iyy="0.00019847383" iyz="0.00000246110" izz="0.00018106988"/>
    </inertial>
    <visual>
      <origin rpy="3.14159265359 0 0" xyz="0 0 0"/>
      <geometry>
        <mesh filename="package://pr2_description/meshes/gripper_v0/l_finger.dae"/>
      </geometry>
      <material name="Grey"/>
    </visual>
    <collision>
      <origin rpy="3.14159265359 0 0" xyz="0 0 0"/>
      <geometry>
        <mesh filename="package://pr2_description/meshes/gripper_v0/l_finger.stl"/>
      </geometry>
    </collision>
  </link>
  <!-- Finger tip -->
  <joint name="r_gripper_l_finger_tip_joint" type="revolute">
    <axis xyz="0 0 -1"/>
    <origin rpy="0 0 0" xyz="0.09137 0.00495 0"/>
    <!-- limits on passive finger and finger top joints without
         transmission are not enforced by safety controllers.
         The lower/upper limits and are enforced in PR2 simulation and
         effort and velocity limits are ignored. This is also needed because
         these joints are declared revolute rather than continuous.-->
    <limit effort="1000.0" lower="0.0" upper="0.548" velocity="0.5"/>
    <dynamics damping="0.001"/>
    <mimic joint="r_gripper_l_finger_joint" multiplier="1" offset="0"/>
    <parent link="r_gripper_l_finger_link"/>
    <child link="r_gripper_l_finger_tip_link"/>
  </joint>
  <link name="r_gripper_l_finger_tip_link">
    <inertial>
      <mass value="0.04419"/>
      <origin rpy="0 0 0" xyz="0.00423 0.00284 0.0"/>
      <inertia ixx="0.00000837047" ixy="0.00000583632" ixz="0.0" iyy="0.00000987067" iyz="0.0" izz="0.00001541768"/>
    </inertial>
    <visual>
      <origin rpy="0 0 0" xyz="0 0 0"/>
      <geometry>
        <mesh filename="package://pr2_description/meshes/gripper_v0/l_finger_tip.dae"/>
      </geometry>
      <material name="Green"/>
    </visual>
    <collision>
      <origin rpy="0 0 0" xyz="0 0 0"/>
      <geometry>
        <mesh filename="package://pr2_description/meshes/gripper_v0/l_finger_tip.stl"/>
      </geometry>
    </collision>
  </link>
  <!-- Finger tip -->
  <joint name="r_gripper_r_finger_tip_joint" type="revolute">
    <axis xyz="0 0 1"/>
    <origin rpy="0 0 0" xyz="0.09137 -0.00495 0"/>
    <!-- limits on passive finger and finger top joints without
         transmission are not enforced by safety controllers.
         The lower/upper limits and are enforced in PR2 simulation and
         effort and velocity limits are ignored. This is also needed because
         these joints are declared revolute rather than continuous.-->
    <limit effort="1000.0" lower="0.0" upper="0.548" velocity="0.5"/>
    <dynamics damping="0.001"/>
    <mimic joint="r_gripper_l_finger_joint" multiplier="1" offset="0"/>
    <parent link="r_gripper_r_finger_link"/>
    <child link="r_gripper_r_finger_tip_link"/>
  </joint>
  <link name="r_gripper_r_finger_tip_link">
    <inertial>
      <mass value="0.04419"/>
      <origin rpy="0 0 0" xyz="0.00423 -0.00284 0.0"/>
      <inertia ixx="0.00000837047" ixy="-0.00000583632" ixz="0.0" iyy="0.00000987067" iyz="0.0" izz="0.00001541768"/>
    </inertial>
    <visual>
      <origin rpy="3.14159265359 0 0" xyz="0 0 0"/>
      <geometry>
        <mesh filename="package://pr2_description/meshes/gripper_v0/l_finger_tip.dae"/>
      </geometry>
      <material name="Green"/>
    </visual>
    <collision>
      <origin rpy="3.14159265359 0 0" xyz="0 0 0"/>
      <geometry>
        <mesh filename="package://pr2_description/meshes/gripper_v0/l_finger_tip.stl"/>
      </geometry>
    </collision>
  </link>
  <!-- Finger proximal digit -->
  <!-- [lr]_gripper_joint is a fictitious joint, used by transmission for controller gap   -->
  <!-- [lr]_gripper_joint is not attached to any link                                      -->
  <!-- [lr]_gripper_joint position is the gap_size                                         -->
  <!-- [lr]_gripper_joint velocity is the gap linear velocity                              -->
  <!-- [lr]_gripper_joint effort   is the gap linear force                                 -->
  <!-- Please refer to function engineering spreadsheet 090224_link_data.xls for           -->
  <!-- the transmission function.                                                          -->
  <!-- Please refer to mechanism_model/src/pr2_gripper_transmission.cpp for implementation.-->
  <!-- gazebo_mimic_pid is for sim only.                                                   -->
  <transmission name="r_gripper_trans" type="pr2_mechanism_model/PR2GripperTransmission">
    <actuator name="r_gripper_motor"/>
    <gap_joint L0="0.0375528" a="0.0683698" b="0.0433849" gear_ratio="40.095" h="0.0" mechanical_reduction="1.0" name="r_gripper_joint" phi0="0.518518122146" r="0.0915" screw_reduction="0.004" t0="-0.0001914" theta0="0.0628824676201"/>
    <!-- if a gazebo joint exists as [l|r]_gripper_joint, use this tag to have
           gripper transmission apply torque directly to prismatic joint
           this should be the default behavior in diamondback, deprecating this flag -->
    <!-- set passive joint angles so things look nice in rviz -->
    <passive_joint name="r_gripper_l_finger_joint"/>
    <passive_joint name="r_gripper_r_finger_joint"/>
    <passive_joint name="r_gripper_r_finger_tip_joint"/>
    <passive_joint name="r_gripper_l_finger_tip_joint"/>
    <!-- screw joint to capture gripper "dynamics" -->
  </transmission>
  <!-- Shoulder pan -->
</robot>

